<?xml version="1.0" ?>
<robot xmlns:xacro="http://ros.org/wiki/xacro">
  <xacro:macro name="motoman_gp400" params="prefix">
    <!-- <xacro:include filename="$(find motoman_resources)/urdf/common_materials.xacro"/> -->

    <!-- Properties -->
    <material name="${prefix}yaskawa_blue">
      <color rgba="0.12941 0.14902 0.74902 1" />
    </material>

    <material name="${prefix}collision_yellow">
      <color rgba="1.0 1.0 0.0 1" />
    </material>

    <material name="${prefix}component_grey">
      <color rgba="0.2 0.2 0.2 1" />
    </material>

    <!-- Link List -->
    <link name="${prefix}base_link">
      <visual>
        <geometry>
          <mesh filename="package://motoman_gp400_support/meshes/visual/GP400_BASE_AXIS.stl"/>
        </geometry>
        <material name="${prefix}yaskawa_blue"/>
      </visual>
      <collision>
        <geometry>
            <mesh filename="package://motoman_gp400_support/meshes/collision/GP400_BASE_AXIS.stl"/>
        </geometry>
        <material name="${prefix}collision_yellow"/>
      </collision>
    </link>

    <link name="${prefix}link_1">
      <visual>
        <geometry>
          <mesh filename="package://motoman_gp400_support/meshes/visual/GP400_S_AXIS.stl"/>
        </geometry>
        <material name="${prefix}yaskawa_blue"/>
      </visual>
      <collision>
        <geometry>
          <mesh filename="package://motoman_gp400_support/meshes/collision/GP400_S_AXIS.stl"/>
        </geometry>
        <material name="${prefix}collision_yellow"/>
      </collision>
    </link>

    <link name="${prefix}link_2">
      <visual>
        <geometry>
          <mesh filename="package://motoman_gp400_support/meshes/visual/GP400_L_AXIS.stl"/>
        </geometry>
        <material name="${prefix}yaskawa_blue"/>
      </visual>
      <collision>
        <geometry>
          <mesh filename="package://motoman_gp400_support/meshes/collision/GP400_L_AXIS.stl"/>
        </geometry>
        <material name="${prefix}collision_yellow"/>
      </collision>
    </link>

    <link name="${prefix}link_3">
      <visual>
        <geometry>
          <mesh filename="package://motoman_gp400_support/meshes/visual/GP400_U_AXIS.stl"/>
        </geometry>
        <material name="${prefix}yaskawa_blue"/>
      </visual>
      <collision>
        <geometry>
          <mesh filename="package://motoman_gp400_support/meshes/collision/GP400_U_AXIS.stl"/>
        </geometry>
        <material name="${prefix}collision_yellow"/>
      </collision>
    </link>

    <link name="${prefix}link_4">
      <visual>
        <geometry>
          <mesh filename="package://motoman_gp400_support/meshes/visual/GP400_R_AXIS.stl"/>
        </geometry>
        <material name="${prefix}yaskawa_blue"/>
      </visual>
      <collision>
        <geometry>
          <mesh filename="package://motoman_gp400_support/meshes/collision/GP400_R_AXIS.stl"/>
        </geometry>
        <material name="${prefix}collision_yellow"/>
      </collision>
    </link>

    <link name="${prefix}link_5">
      <visual>
        <geometry>
          <mesh filename="package://motoman_gp400_support/meshes/visual/GP400_B_AXIS.stl"/>
        </geometry>
        <material name="${prefix}yaskawa_blue"/>
      </visual>
      <collision>
        <geometry>
          <mesh filename="package://motoman_gp400_support/meshes/collision/GP400_B_AXIS.stl"/>
        </geometry>
        <material name="${prefix}collision_yellow"/>
      </collision>
    </link>

    <link name="${prefix}link_6">
      <visual>
        <geometry>
          <mesh filename="package://motoman_gp400_support/meshes/visual/GP400_T_AXIS.stl"/>
        </geometry>
        <material name="${prefix}yaskawa_blue"/>
      </visual>
      <collision>
        <geometry>
          <mesh filename="package://motoman_gp400_support/meshes/collision/GP400_T_AXIS.stl"/>
        </geometry>
        <material name="${prefix}collision_yellow"/>
      </collision>
    </link>

    <!-- Balancer A parallell to Link L -->
    <link name="${prefix}balancer_A">
      <visual>
        <geometry>
          <mesh filename="package://motoman_gp400_support/meshes/visual/GP400_LINK_A_AXIS.stl"/>
        </geometry>
        <material name="${prefix}yaskawa_blue"/>
      </visual>
      <collision>
        <geometry>
          <mesh filename="package://motoman_gp400_support/meshes/collision/GP400_LINK_A_AXIS.stl"/>
        </geometry>
        <material name="${prefix}collision_yellow"/>
      </collision>
    </link>

    <!-- Balancer B parallell to Link U -->
    <link name="${prefix}balancer_B">
      <visual>
        <geometry>
          <mesh filename="package://motoman_gp400_support/meshes/visual/GP400_LINK_B_AXIS.stl"/>
        </geometry>
        <material name="${prefix}yaskawa_blue"/>
      </visual>
      <collision>
        <geometry>
          <mesh filename="package://motoman_gp400_support/meshes/visual/GP400_LINK_B_AXIS.stl"/>
        </geometry>
        <material name="${prefix}collision_yellow"/>
      </collision>
    </link>

    <!-- Cylinder Box -->
    <link name="${prefix}cylinderbox">
      <visual>
        <geometry>
          <mesh filename="package://motoman_gp400_support/meshes/visual/GP400_BALANCER_AXIS.stl"/>
        </geometry>
        <material name="${prefix}component_grey"/>
      </visual>
      <collision>
        <geometry>
          <mesh filename="package://motoman_gp400_support/meshes/collision/GP400_BALANCER_AXIS.stl"/>
        </geometry>
        <material name="${prefix}Collision_yellow"/>
      </collision>
    </link>

    <link name="${prefix}tool0"/>
    <link name="${prefix}fakelink"/>
    <!-- End of Link List -->

    <!-- Joint List -->
    <!-- S-Axis -->
    <joint name="${prefix}joint_1" type="revolute">
      <parent link="${prefix}base_link"/>
      <child link="${prefix}link_1"/>
      <origin xyz="0.000 0.000 0.1445" rpy="0 0 0" />
      <axis xyz="0 0 1" />
      <limit lower="${radians(-180)}" upper="${radians(180)}" velocity="1.78" effort="0"/>
    </joint>

    <!-- L-Axis -->
    <joint name="${prefix}joint_2" type="revolute">
      <parent link="${prefix}link_1"/>
      <child link="${prefix}link_2"/>
      <origin xyz="0.400 0.000 0.7555" rpy="0 0 0" />
      <axis xyz="0 1 0" />
      <limit lower="${radians(-55)}" upper="${radians(61)}" velocity="1.69" effort="0"/>
    </joint>

    <!-- U-Axis -->
    <joint name="${prefix}joint_3" type="revolute">
      <parent link="${prefix}link_2"/>
      <child link="${prefix}link_3"/>
      <origin xyz="0.000 0.000 1.050" rpy="0 0 0" />
      <axis xyz="0 -1 0" />
      <!-- <limit lower="${radians(-18)}" upper="${radians(113)}" velocity="1.69" effort="0"/> -->
      <!-- <limit lower="${radians(-52)}" upper="${radians(61)}" velocity="1.69" effort="0"/> -->
      <limit lower="${radians(-61)}" upper="${radians(17)}" velocity="1.69" effort="0"/>
      <!-- Lower = -113 + 61 -->
      <!-- Upper = 61-->
    </joint>

    <!-- R-Axis -->
    <joint name="${prefix}joint_4" type="revolute">
      <parent link="${prefix}link_3"/>
      <child link="${prefix}link_4"/>
      <origin xyz="1.31772 0.000 0.250" rpy="0 0 0" />
      <axis xyz="-1 0 0" />
      <!-- <limit lower="${radians(-360)}" upper="${radians(360)}" velocity="1.40" effort="0"/> -->
      <limit lower="${radians(-120)}" upper="${radians(120)}" velocity="1.40" effort="0"/>
    </joint>

    <!-- B-Axis -->
    <joint name="${prefix}joint_5" type="revolute">
      <parent link="${prefix}link_4"/>
      <child link="${prefix}link_5"/>
      <origin xyz="0.28728 0.000 0.000" rpy="${radians(180)} 0 0" />
      <axis xyz="0 1 0" />
      <limit lower="${radians(-115)}" upper="${radians(115)}" velocity="1.40" effort="0"/>
    </joint>
    
    <!-- T-Axis -->
    <joint name="${prefix}joint_6" type="revolute">
      <parent link="${prefix}link_5"/>
      <child link="${prefix}link_6"/>
      <origin xyz="0.266 0.000 0.000" rpy="0 0 0" />
      <axis xyz="-1 0 0" />
      <!-- <limit lower="${radians(-360)}" upper="${radians(360)}" velocity="3.00" effort="0"/> -->
      <limit lower="${radians(-120)}" upper="${radians(120)}" velocity="3.00" effort="0"/>
    </joint>

    <!-- EOAT -->
    <joint name="${prefix}joint_6-tool0" type="fixed">
      <origin xyz="0.034 0.000 0.000" rpy="0 ${radians(90)} 0" />
      <parent link="${prefix}link_6"/>
      <child link="${prefix}tool0"/>
    </joint>

    <!-- Fakelinke for Balancer B -->
    <joint name="${prefix}link1_adjustment" type="revolute">
      <origin xyz="0.400 0.000 0.7555" rpy="0 0 0"/>
      <parent link="${prefix}link_1"/>
      <child link="${prefix}fakelink"/>
      <axis xyz="0 1 0"/>
      <mimic joint="${prefix}joint_2" multiplier="1"/>
      <limit lower="${radians(-113)}" upper="${radians(61)}" velocity="1.69" effort="0"/>
    </joint>

    <!-- Balancer B parallell to Link U -->
    <joint name="${prefix}balancer_B" type="revolute">
      <parent link="${prefix}fakelink"/>
      <child link="${prefix}balancer_B"/>
      <origin xyz="0.000 -0.100 0.000" rpy="0 0 0" />
      <axis xyz="0 -1 0" />
      <mimic joint="${prefix}joint_3" multiplier="1.0"/>
      <limit lower="${radians(-113)}" upper="${radians(61)}" velocity="1.69" effort="0"/>
    </joint>
    
    <!-- Balancer A parallell to Link L -->
    <joint name="${prefix}balancer_A" type="revolute">
      <parent link="${prefix}balancer_B"/>
      <child link="${prefix}balancer_A"/>
      <origin xyz="-0.500 0.000 0.000" rpy="0 0 0" />
      <axis xyz="0 1 0" />
      <mimic joint="${prefix}joint_3" multiplier="1.0"/>
      <limit lower="${radians(-55)}" upper="${radians(61)}" velocity="1.69" effort="0"/>
    </joint>

    <!-- Cylinder Box -->
    <joint name="${prefix}cylinderbox" type="revolute">
      <parent link="${prefix}link_1"/>
      <child link="${prefix}cylinderbox"/>
      <origin xyz="-0.191 0.059 0.651" rpy="0 ${radians(-10)} 0" />
      <axis xyz="0 -1 0" />
      <mimic joint="${prefix}joint_2" multiplier="0.35"/>
      <limit lower="${radians(-55)}" upper="${radians(61)}" velocity="1.69" effort="0"/>
    </joint>
    <!-- End of joint List -->
  </xacro:macro>
</robot>
